<!DOCTYPE html>
<html lang="en">
<head>
    <meta charset="UTF-8">
    <title>promise 的all</title>
</head>
<body>
<p>promises是包含 多 个 Promise 实例的数组，
    只有这 多 个实例的状态都变成fulfilled，或者其中有一个变为rejected，
    才会调用Promise.all方法后面的回调函数。</p>
</body>
<script>
    const p1 = new Promise((resolve, reject) => {
        resolve('hello');
    })
        .then(result => result)
        .catch(e => e);

    const p2 = new Promise((resolve, reject) => {
        throw new Error('报错了');
    })
        .then(result => result)
        .catch(e => e); // 如果没有 catch 时 ，他会调用all中抛出异常的方法

    Promise.all([p1, p2])
        .then(result => console.log(result))
        .catch(e => console.log(e));
    // ["hello", Error: 报错了] ---- 这是rejected 输出的语句
    // Array(2)  0:hello 1:Error: 报错了   --- 这是resolv的执行结果
</script>
</html>